Workbook

Sheet HOW TO PLAY
A1: HOW TO PLAY — and what you are actually testing
A4: WHY THIS EXISTS
B5: Every system in the design brief assumes one thing is true: that nudging an invisible system and watching the consequences arrive four to eight seasons later, in a country you did not target, is FUN. Nothing written so far proves that. This workbook is the cheapest possible test of it. Ten years, one homeland, eight regions, nine tools.
B6: If forty seasons of this is tense and legible and you want a forty-first, the design is sound and worth building. If it feels like filling in a tax return, the core loop needs rework and you have found that out in an afternoon instead of a year.
A8: THE SETUP
B9: You direct a national environmental warfare programme, 1946-1955. Your homeland is the North American Plains: a wheat and maize exporter. Your budget comes from two places — a share of homeland farm revenue, and an appropriation driven by MANDATE, which rises when the world's weather looks frightening.
B10: Read that last part again. A calm world defunds you.
A12: HOW A SEASON WORKS
A13: 1. Look | B13: Read the row above. What landed? Which region is worst hit? What happened to the grain price and your revenue?
A14: 2. Commit | B14: On the current row, choose up to two operations from the dropdowns in columns D and F, and a target region in E and G where the tool needs one. Set containment spend in H.
A15: 3. Resolve | B15: The row fills in. Most of what you just ordered will NOT appear this season — check the lag in CAPABILITIES.
A16: 4. Move down | B16: One row at a time. Do not scroll ahead and do not undo. Playing it honestly is the whole experiment.
A18: THE FOUR THINGS TO WATCH
A19: Treasury (I) | B19: Runs out and you cannot act. Ops are expensive; containment is worse.
A20: Mandate (J) | B20: Rises with global weather severity. This is your appropriation. It is also the trap.
A21: Price / Revenue (M, N) | B21: You export wheat. Someone else's failed harvest is your windfall. Someone else's bumper crop is your problem. This is the whole economic game.
A22: Dossier (Q, R) | B22: Hidden accumulation of evidence. You never see the number in the real game — only column R. At 200 you are exposed and the run is over.
A24: WHAT TO TRY
A25: The obvious play | B25: Cloud Seeding on your homeland every season. Watch what it costs you and what it fails to achieve.
A26: The real play | B26: Find a region that competes with you in wheat. Look up its teleconnections in GRAPH. Move the driver, not the region — it is slower, but the anomaly arrives looking like climate.
A27: The elegant play | B27: Wait. Watch the ENSO column in CLIMATE. When a strong natural swing is already coming, act into it: your anomaly hides inside the envelope and your signature multiplier collapses. Patience is a mechanic.
A28: Fire Enablement | B28: Only fully effective if the target was already dry last season. Build the drought first, then ignite. This is the composite mechanic in miniature and it is the most interesting tool in the catalogue.
A29: The energy ledger | B29: Ocean Thermal, Aerosol and ENSO Forcing all DISPLACE — check the CAPABILITIES sheet. What you move surfaces somewhere else, several seasons later, with the opposite sign. This is where the game bites.
A31: WHAT TO RECORD
B32: Keep a note beside you. After every season write one line: what you expected, and what happened. At the end, count how many times those two matched. If it is near zero, the model is noise and the player cannot learn it. If it is near forty, it is too legible and there is no tension. Somewhere in the middle is a game.
B33: Also record: which season was the most fun, and why. That answer is worth more than the rest of this workbook.
A35: WHAT THIS IS NOT
B36: Not balanced. Not a spec. Not a model of the real climate — the graph is real in its RELATIONSHIPS and invented in its NUMBERS. Every value on ASSUMPTIONS is a guess. Change them freely; that is what they are for.
A38: SHEETS
A39: PLAY | B39: Where you play. Blue cells are yours.
A40: CLIMATE | B40: The natural background. In the real game this is observed ENSO/IOD/Atlantic SST data.
A41: REGIONS | B41: Nodes: crop, supply weight, yield sensitivity, variance envelope.
A42: GRAPH | B42: Edges: coefficients and lags. Real climatology, invented magnitudes.
A43: CAPABILITIES | B43: The nine tools and their parameters.
A44: ASSUMPTIONS | B44: Every dial in the model, plus the exposure ladder.
A45: ENGINE | B45: The resolution maths. Computed; do not edit.

Sheet PLAY
A1: FORCE MAJEURE — CORE LOOP PROTOTYPE
A2: You are the Directorate. 1946-1955. Homeland: North American Plains (wheat and maize exporter).
A4: THE ONLY QUESTION THIS PROTOTYPE ASKS: is it fun to nudge an invisible system and watch the consequences arrive four to eight seasons later in the wrong country? Fill the four BLUE columns, one season at a time, top to bottom. Do not read ahead. Read HOW TO PLAY first.
A7: t | B7: Year | C7: Qtr | D7: OPERATION A | E7: Target region | F7: OPERATION B | G7: Target region | H7: Containment $ | I7: Treasury | J7: Mandate | K7: Homeland yield | L7: World supply | M7: Grain price | N7: Revenue | O7: Worst-hit region | P7: its yield | Q7: Dossier | R7: WHAT YOU ARE TOLD | S7: STATUS
A8: 1 | B8: =CLIMATE!B8 -> 1946 | C8: =CLIMATE!C8 -> Winter | D8: Cloud Seeding | E8: Sahel | F8: — none — | H8: 0 | I8: =ENGINE!$BO8 -> 89.874567 | J8: =ENGINE!$BK8 -> 29.792581 | K8: =ENGINE!$AY8 -> 100 | L8: =ENGINE!$BG8 -> 95.596576 | M8: =ENGINE!$BH8 -> 108.44357 | N8: =ENGINE!$BI8 -> 92.177032 | O8: =INDEX(REGIONS!$B$7:$B$14,MATCH(MIN(ENGINE!$AY8:$BF8),ENGINE!$AY8:$BF8,0)) -> Eastern Australia | P8: =MIN(ENGINE!$AY8:$BF8) -> 77.41562 | Q8: =ENGINE!$BQ8 -> 0 | R8: =INDEX(ASSUMPTIONS!$B$28:$B$34,MATCH(ENGINE!$BQ8,ASSUMPTIONS!$A$28:$A$34,1)) -> Nothing. No one is looking. | S8: =IF(ENGINE!$BQ8>=200,"EXPOSED — run over",IF(ENGINE!$BO8<0,"INSOLVENT — programme suspended",IF(AND($A8>8,ENGINE!$BK8<=ASSUMPTIONS!$B$12+1),"Committee is asking what you are for","running"))) -> running
A9: 2 | B9: =CLIMATE!B9 -> 1946 | C9: =CLIMATE!C9 -> Spring | D9: — none — | F9: — none — | H9: 0 | I9: =ENGINE!$BO9 -> 98.833468 | J9: =ENGINE!$BK9 -> 33.286162 | K9: =ENGINE!$AY9 -> 100 | L9: =ENGINE!$BG9 -> 95.885337 | M9: =ENGINE!$BH9 -> 107.85643 | N9: =ENGINE!$BI9 -> 91.677966 | O9: =INDEX(REGIONS!$B$7:$B$14,MATCH(MIN(ENGINE!$AY9:$BF9),ENGINE!$AY9:$BF9,0)) -> Eastern Australia | P9: =MIN(ENGINE!$AY9:$BF9) -> 74.55822 | Q9: =ENGINE!$BQ9 -> 2.1120288 | R9: =INDEX(ASSUMPTIONS!$B$28:$B$34,MATCH(ENGINE!$BQ9,ASSUMPTIONS!$A$28:$A$34,1)) -> Nothing. No one is looking. | S9: =IF(ENGINE!$BQ9>=200,"EXPOSED — run over",IF(ENGINE!$BO9<0,"INSOLVENT — programme suspended",IF(AND($A9>8,ENGINE!$BK9<=ASSUMPTIONS!$B$12+1),"Committee is asking what you are for","running"))) -> running
A10: 3 | B10: =CLIMATE!B10 -> 1946 | C10: =CLIMATE!C10 -> Summer | D10: — none — | F10: — none — | H10: 0 | I10: =ENGINE!$BO10 -> 106.64558 | J10: =ENGINE!$BK10 -> 31.854718 | K10: =ENGINE!$AY10 -> 100 | L10: =ENGINE!$BG10 -> 95.206901 | M10: =ENGINE!$BH10 -> 109.24381 | N10: =ENGINE!$BI10 -> 92.857236 | O10: =INDEX(REGIONS!$B$7:$B$14,MATCH(MIN(ENGINE!$AY10:$BF10),ENGINE!$AY10:$BF10,0)) -> Eastern Australia | P10: =MIN(ENGINE!$AY10:$BF10) -> 73.23508 | Q10: =ENGINE!$BQ10 -> 2.0275477 | R10: =INDEX(ASSUMPTIONS!$B$28:$B$34,MATCH(ENGINE!$BQ10,ASSUMPTIONS!$A$28:$A$34,1)) -> Nothing. No one is looking. | S10: =IF(ENGINE!$BQ10>=200,"EXPOSED — run over",IF(ENGINE!$BO10<0,"INSOLVENT — programme suspended",IF(AND($A10>8,ENGINE!$BK10<=ASSUMPTIONS!$B$12+1),"Committee is asking what you are for","running"))) -> running
A11: 4 | B11: =CLIMATE!B11 -> 1946 | C11: =CLIMATE!C11 -> Autumn | D11: — none — | F11: — none — | H11: 0 | I11: =ENGINE!$BO11 -> 112.37145 | J11: =ENGINE!$BK11 -> 29.505952 | K11: =ENGINE!$AY11 -> 100 | L11: =ENGINE!$BG11 -> 95.07593 | M11: =ENGINE!$BH11 -> 109.51484 | N11: =ENGINE!$BI11 -> 93.08761 | O11: =INDEX(REGIONS!$B$7:$B$14,MATCH(MIN(ENGINE!$AY11:$BF11),ENGINE!$AY11:$BF11,0)) -> Sahel | P11: =MIN(ENGINE!$AY11:$BF11) -> 86.90328 | Q11: =ENGINE!$BQ11 -> 1.9464458 | R11: =INDEX(ASSUMPTIONS!$B$28:$B$34,MATCH(ENGINE!$BQ11,ASSUMPTIONS!$A$28:$A$34,1)) -> Nothing. No one is looking. | S11: =IF(ENGINE!$BQ11>=200,"EXPOSED — run over",IF(ENGINE!$BO11<0,"INSOLVENT — programme suspended",IF(AND($A11>8,ENGINE!$BK11<=ASSUMPTIONS!$B$12+1),"Committee is asking what you are for","running"))) -> running
A12: 5 | B12: =CLIMATE!B12 -> 1947 | C12: =CLIMATE!C12 -> Winter | D12: — none — | F12: — none — | H12: 0 | I12: =ENGINE!$BO12 -> 117.20732 | J12: =ENGINE!$BK12 -> 28.68355 | K12: =ENGINE!$AY12 -> 97.1832 | L12: =ENGINE!$BG12 -> 94.283402 | M12: =ENGINE!$BH12 -> 111.17741 | N12: =ENGINE!$BI12 -> 91.838901 | O12: =INDEX(REGIONS!$B$7:$B$14,MATCH(MIN(ENGINE!$AY12:$BF12),ENGINE!$AY12:$BF12,0)) -> Horn of Africa | P12: =MIN(ENGINE!$AY12:$BF12) -> 80.6744 | Q12: =ENGINE!$BQ12 -> 1.8685879 | R12: =INDEX(ASSUMPTIONS!$B$28:$B$34,MATCH(ENGINE!$BQ12,ASSUMPTIONS!$A$28:$A$34,1)) -> Nothing. No one is looking. | S12: =IF(ENGINE!$BQ12>=200,"EXPOSED — run over",IF(ENGINE!$BO12<0,"INSOLVENT — programme suspended",IF(AND($A12>8,ENGINE!$BK12<=ASSUMPTIONS!$B$12+1),"Committee is asking what you are for","running"))) -> running
A13: 6 | B13: =CLIMATE!B13 -> 1947 | C13: =CLIMATE!C13 -> Spring | D13: — none — | F13: — none — | H13: 0 | I13: =ENGINE!$BO13 -> 124.66196 | J13: =ENGINE!$BK13 -> 31.399228 | K13: =ENGINE!$AY13 -> 98.3774 | L13: =ENGINE!$BG13 -> 94.099619 | M13: =ENGINE!$BH13 -> 111.56856 | N13: =ENGINE!$BI13 -> 93.294515 | O13: =INDEX(REGIONS!$B$7:$B$14,MATCH(MIN(ENGINE!$AY13:$BF13),ENGINE!$AY13:$BF13,0)) -> South Asia | P13: =MIN(ENGINE!$AY13:$BF13) -> 84.95392 | Q13: =ENGINE!$BQ13 -> 1.7938444 | R13: =INDEX(ASSUMPTIONS!$B$28:$B$34,MATCH(ENGINE!$BQ13,ASSUMPTIONS!$A$28:$A$34,1)) -> Nothing. No one is looking. | S13: =IF(ENGINE!$BQ13>=200,"EXPOSED — run over",IF(ENGINE!$BO13<0,"INSOLVENT — programme suspended",IF(AND($A13>8,ENGINE!$BK13<=ASSUMPTIONS!$B$12+1),"Committee is asking what you are for","running"))) -> running
A14: 7 | B14: =CLIMATE!B14 -> 1947 | C14: =CLIMATE!C14 -> Summer | D14: — none — | F14: — none — | H14: 0 | I14: =ENGINE!$BO14 -> 128.56502 | J14: =ENGINE!$BK14 -> 28.037191 | K14: =ENGINE!$AY14 -> 100 | L14: =ENGINE!$BG14 -> 97.530471 | M14: =ENGINE!$BH14 -> 104.60379 | N14: =ENGINE!$BI14 -> 88.913221 | O14: =INDEX(REGIONS!$B$7:$B$14,MATCH(MIN(ENGINE!$AY14:$BF14),ENGINE!$AY14:$BF14,0)) -> Eastern Australia | P14: =MIN(ENGINE!$AY14:$BF14) -> 84.12414 | Q14: =ENGINE!$BQ14 -> 1.7220906 | R14: =INDEX(ASSUMPTIONS!$B$28:$B$34,MATCH(ENGINE!$BQ14,ASSUMPTIONS!$A$28:$A$34,1)) -> Nothing. No one is looking. | S14: =IF(ENGINE!$BQ14>=200,"EXPOSED — run over",IF(ENGINE!$BO14<0,"INSOLVENT — programme suspended",IF(AND($A14>8,ENGINE!$BK14<=ASSUMPTIONS!$B$12+1),"Committee is asking what you are for","running"))) -> running
A15: 8 | B15: =CLIMATE!B15 -> 1947 | C15: =CLIMATE!C15 -> Autumn | D15: — none — | F15: — none — | H15: 0 | I15: =ENGINE!$BO15 -> 132.12531 | J15: =ENGINE!$BK15 -> 28 | K15: =ENGINE!$AY15 -> 97.543 | L15: =ENGINE!$BG15 -> 97.776814 | M15: =ENGINE!$BH15 -> 104.12989 | N15: =ENGINE!$BI15 -> 86.335706 | O15: =INDEX(REGIONS!$B$7:$B$14,MATCH(MIN(ENGINE!$AY15:$BF15),ENGINE!$AY15:$BF15,0)) -> Southeast Asia | P15: =MIN(ENGINE!$AY15:$BF15) -> 94.60384 | Q15: =ENGINE!$BQ15 -> 1.653207 | R15: =INDEX(ASSUMPTIONS!$B$28:$B$34,MATCH(ENGINE!$BQ15,ASSUMPTIONS!$A$28:$A$34,1)) -> Nothing. No one is looking. | S15: =IF(ENGINE!$BQ15>=200,"EXPOSED — run over",IF(ENGINE!$BO15<0,"INSOLVENT — programme suspended",IF(AND($A15>8,ENGINE!$BK15<=ASSUMPTIONS!$B$12+1),"Committee is asking what you are for","running"))) -> running
A16: 9 | B16: =CLIMATE!B16 -> 1948 | C16: =CLIMATE!C16 -> Winter | D16: — none — | F16: — none — | H16: 0 | I16: =ENGINE!$BO16 -> 136.70419 | J16: =ENGINE!$BK16 -> 29.17999 | K16: =ENGINE!$AY16 -> 100 | L16: =ENGINE!$BG16 -> 99.36897 | M16: =ENGINE!$BH16 -> 101.14597 | N16: =ENGINE!$BI16 -> 85.974075 | O16: =INDEX(REGIONS!$B$7:$B$14,MATCH(MIN(ENGINE!$AY16:$BF16),ENGINE!$AY16:$BF16,0)) -> Black Sea Steppe | P16: =MIN(ENGINE!$AY16:$BF16) -> 96.05606 | Q16: =ENGINE!$BQ16 -> 1.5870787 | R16: =INDEX(ASSUMPTIONS!$B$28:$B$34,MATCH(ENGINE!$BQ16,ASSUMPTIONS!$A$28:$A$34,1)) -> Nothing. No one is looking. | S16: =IF(ENGINE!$BQ16>=200,"EXPOSED — run over",IF(ENGINE!$BO16<0,"INSOLVENT — programme suspended",IF(AND($A16>8,ENGINE!$BK16<=ASSUMPTIONS!$B$12+1),"Committee is asking what you are for","running"))) -> running
A17: 10 | B17: =CLIMATE!B17 -> 1948 | C17: =CLIMATE!C17 -> Spring | D17: — none — | F17: — none — | H17: 0 | I17: =ENGINE!$BO17 -> 149.4067 | J17: =ENGINE!$BK17 -> 38.180086 | K17: =ENGINE!$AY17 -> 100 | L17: =ENGINE!$BG17 -> 99.243176 | M17: =ENGINE!$BH17 -> 101.37686 | N17: =ENGINE!$BI17 -> 86.170328 | O17: =INDEX(REGIONS!$B$7:$B$14,MATCH(MIN(ENGINE!$AY17:$BF17),ENGINE!$AY17:$BF17,0)) -> La Plata Basin | P17: =MIN(ENGINE!$AY17:$BF17) -> 96.696 | Q17: =ENGINE!$BQ17 -> 1.5235956 | R17: =INDEX(ASSUMPTIONS!$B$28:$B$34,MATCH(ENGINE!$BQ17,ASSUMPTIONS!$A$28:$A$34,1)) -> Nothing. No one is looking. | S17: =IF(ENGINE!$BQ17>=200,"EXPOSED — run over",IF(ENGINE!$BO17<0,"INSOLVENT — programme suspended",IF(AND($A17>8,ENGINE!$BK17<=ASSUMPTIONS!$B$12+1),"Committee is asking what you are for","running"))) -> running
A18: 11 | B18: =CLIMATE!B18 -> 1948 | C18: =CLIMATE!C18 -> Summer | D18: — none — | F18: — none — | H18: 0 | I18: =ENGINE!$BO18 -> 156.00786 | J18: =ENGINE!$BK18 -> 31.712149 | K18: =ENGINE!$AY18 -> 92.8992 | L18: =ENGINE!$BG18 -> 96.729292 | M18: =ENGINE!$BH18 -> 106.16848 | N18: =ENGINE!$BI18 -> 83.835215 | O18: =INDEX(REGIONS!$B$7:$B$14,MATCH(MIN(ENGINE!$AY18:$BF18),ENGINE!$AY18:$BF18,0)) -> La Plata Basin | P18: =MIN(ENGINE!$AY18:$BF18) -> 89.402 | Q18: =ENGINE!$BQ18 -> 1.4626518 | R18: =INDEX(ASSUMPTIONS!$B$28:$B$34,MATCH(ENGINE!$BQ18,ASSUMPTIONS!$A$28:$A$34,1)) -> Nothing. No one is looking. | S18: =IF(ENGINE!$BQ18>=200,"EXPOSED — run over",IF(ENGINE!$BO18<0,"INSOLVENT — programme suspended",IF(AND($A18>8,ENGINE!$BK18<=ASSUMPTIONS!$B$12+1),"Committee is asking what you are for","running"))) -> running
A19: 12 | B19: =CLIMATE!B19 -> 1948 | C19: =CLIMATE!C19 -> Autumn | D19: — none — | F19: — none — | H19: 0 | I19: =ENGINE!$BO19 -> 159.30489 | J19: =ENGINE!$BK19 -> 28 | K19: =ENGINE!$AY19 -> 96.255 | L19: =ENGINE!$BG19 -> 98.45526 | M19: =ENGINE!$BH19 -> 102.84186 | N19: =ENGINE!$BI19 -> 84.141871 | O19: =INDEX(REGIONS!$B$7:$B$14,MATCH(MIN(ENGINE!$AY19:$BF19),ENGINE!$AY19:$BF19,0)) -> Horn of Africa | P19: =MIN(ENGINE!$AY19:$BF19) -> 95.19016 | Q19: =ENGINE!$BQ19 -> 1.4041457 | R19: =INDEX(ASSUMPTIONS!$B$28:$B$34,MATCH(ENGINE!$BQ19,ASSUMPTIONS!$A$28:$A$34,1)) -> Nothing. No one is looking. | S19: =IF(ENGINE!$BQ19>=200,"EXPOSED — run over",IF(ENGINE!$BO19<0,"INSOLVENT — programme suspended",IF(AND($A19>8,ENGINE!$BK19<=ASSUMPTIONS!$B$12+1),"Committee is asking what you are for","running"))) -> Committee is asking what you are for
A20: 13 | B20: =CLIMATE!B20 -> 1949 | C20: =CLIMATE!C20 -> Winter | D20: — none — | F20: — none — | H20: 0 | I20: =ENGINE!$BO20 -> 162.98667 | J20: =ENGINE!$BK20 -> 28 | K20: =ENGINE!$AY20 -> 94.946 | L20: =ENGINE!$BG20 -> 95.700012 | M20: =ENGINE!$BH20 -> 108.23268 | N20: =ENGINE!$BI20 -> 87.348211 | O20: =INDEX(REGIONS!$B$7:$B$14,MATCH(MIN(ENGINE!$AY20:$BF20),ENGINE!$AY20:$BF20,0)) -> Horn of Africa | P20: =MIN(ENGINE!$AY20:$BF20) -> 81.93272 | Q20: =ENGINE!$BQ20 -> 1.3479799 | R20: =INDEX(ASSUMPTIONS!$B$28:$B$34,MATCH(ENGINE!$BQ20,ASSUMPTIONS!$A$28:$A$34,1)) -> Nothing. No one is looking. | S20: =IF(ENGINE!$BQ20>=200,"EXPOSED — run over",IF(ENGINE!$BO20<0,"INSOLVENT — programme suspended",IF(AND($A20>8,ENGINE!$BK20<=ASSUMPTIONS!$B$12+1),"Committee is asking what you are for","running"))) -> Committee is asking what you are for
... A47: 40 | B47: =CLIMATE!B47 -> 1955 | C47: =CLIMATE!C47 -> Autumn | D47: — none — | F47: — none — | H47: 0 | I47: =ENGINE!$BO47 -> 300.58709 | J47: =ENGINE!$BK47 -> 30.77116 | K47: =ENGINE!$AY47 -> 98.0386 | L47: =ENGINE!$BG47 -> 95.43899 | M47: =ENGINE!$BH47 -> 108.76608 | N47: =ENGINE!$BI47 -> 90.637834 | O47: =INDEX(REGIONS!$B$7:$B$14,MATCH(MIN(ENGINE!$AY47:$BF47),ENGINE!$AY47:$BF47,0)) -> Horn of Africa | P47: =MIN(ENGINE!$AY47:$BF47) -> 78.72616 | Q47: =ENGINE!$BQ47 -> 0.44772021 | R47: =INDEX(ASSUMPTIONS!$B$28:$B$34,MATCH(ENGINE!$BQ47,ASSUMPTIONS!$A$28:$A$34,1)) -> Nothing. No one is looking. | S47: =IF(ENGINE!$BQ47>=200,"EXPOSED — run over",IF(ENGINE!$BO47<0,"INSOLVENT — programme suspended",IF(AND($A47>8,ENGINE!$BK47<=ASSUMPTIONS!$B$12+1),"Committee is asking what you are for","running"))) -> running

Sheet CLIMATE
A1: CLIMATE SUBSTRATE — natural background variability
A3: Natural driver values and per-region weather noise. In the real game these come from observed records (ONI/ENSO 1950-present, IOD, Atlantic SST, ERA5 reanalysis). Here they are a deterministic stand-in so runs are replayable. BLUE = editable input.
A6: Season | B6: Year | C6: Qtr | D6: ENSO (natural) | E6: IOD (natural) | F6: NATL (natural) | G6: GLOBAL (natural) | H6: noise: North American Plains | I6: noise: Black Sea Steppe | J6: noise: La Plata Basin | K6: noise: South Asia | L6: noise: Southeast Asia | M6: noise: Eastern Australia | N6: noise: Sahel | O6: noise: Horn of Africa
A8: 1 | B8: 1946 | C8: Winter | D8: 1.297 | E8: 0.371 | F8: 0.215 | G8: 0 | H8: 0.2 | I8: 0.224 | J8: 0.153 | K8: 0.013 | L8: 0.338 | M8: 0.149 | N8: -0.04 | O8: -0.225
A9: 2 | B9: 1946 | C9: Spring | D9: 1.188 | E9: 0.084 | F9: 0.074 | G9: 0 | H9: 0.039 | I9: 0.012 | J9: 0.408 | K9: 0.272 | L9: 0.129 | M9: -0.008 | N9: -0.135 | O9: -0.253
A10: 3 | B10: 1946 | C10: Summer | D10: 0.675 | E10: -0.667 | F10: 0.024 | G10: 0 | H10: 0.311 | I10: 0.284 | J10: 0.237 | K10: 0.194 | L10: 0.165 | M10: -0.351 | N10: -0.354 | O10: -0.348
A11: 4 | B11: 1946 | C11: Autumn | D11: 0.489 | E11: -1.236 | F11: 0.309 | G11: 0 | H11: 0.091 | I11: -0.198 | J11: 0.033 | K11: -0.214 | L11: 0.055 | M11: -0.163 | N11: -0.372 | O11: -0.074
A12: 5 | B12: 1947 | C12: Winter | D12: 0.702 | E12: -0.658 | F12: 0.547 | G12: 0 | H12: -0.329 | I12: -0.241 | J12: -0.129 | K12: -0.001 | L12: -0.362 | M12: -0.217 | N12: -0.068 | O12: -0.417
A13: 6 | B13: 1947 | C13: Spring | D13: 0.229 | E13: 0.532 | F13: 0.941 | G13: 0 | H13: -0.121 | I13: -0.057 | J13: 0.015 | K13: -0.409 | L13: -0.331 | M13: -0.252 | N13: -0.174 | O13: -0.096
A14: 7 | B14: 1947 | C14: Summer | D14: 0.048 | E14: 0.464 | F14: 0.385 | G14: 0 | H14: 0.057 | I14: -0.119 | J14: -0.298 | K14: 0.02 | L14: -0.162 | M14: -0.347 | N14: -0.032 | O14: -0.218
A15: 8 | B15: 1947 | C15: Autumn | D15: -0.85 | E15: 0.368 | F15: 0.602 | G15: 0 | H15: 0.061 | I15: -0.135 | J15: 0.168 | K15: -0.028 | L15: -0.224 | M15: 0.079 | N15: -0.117 | O15: 0.187
A16: 9 | B16: 1948 | C16: Winter | D16: -1.58 | E16: 0.727 | F16: 0.214 | G16: 0 | H16: 0.41 | I16: -0.045 | J16: 0.002 | K16: 0.051 | L16: 0.101 | M16: 0.153 | N16: 0.206 | O16: 0.26
A17: 10 | B17: 1948 | C17: Spring | D17: -1.107 | E17: 0.664 | F17: 0.327 | G17: 0 | H17: 0.43 | I17: 0.313 | J17: 0.189 | K17: 0.06 | L17: 0.429 | M17: 0.298 | N17: 0.167 | O17: 0.036
A18: 11 | B18: 1948 | C18: Summer | D18: -0.472 | E18: -0.06 | F18: 0.552 | G18: 0 | H18: -0.127 | I18: -0.034 | J18: 0.033 | K18: 0.085 | L18: 0.126 | M18: 0.161 | N18: 0.192 | O18: 0.22
A19: 12 | B19: 1948 | C19: Autumn | D19: -0.054 | E19: -0.885 | F19: 0.401 | G19: 0 | H19: 0.052 | I19: -0.058 | J19: 0.312 | K19: 0.161 | L19: -0.008 | M19: 0.311 | N19: 0.121 | O19: 0.424
... A47: 40 | B47: 1955 | C47: Autumn | D47: -0.249 | E47: -1.197 | F47: -0.122 | G47: 0 | H47: 0.116 | I47: -0.25 | J47: -0.287 | K47: 0.036 | L47: -0.254 | M47: -0.287 | N47: -0.006 | O47: 0.194

Sheet REGIONS
A1: REGION NODES
A3: Each region is a node on the teleconnection graph. SIGMA is the natural variance envelope — the width of 'could have happened anyway'. It widens every season (see ASSUMPTIONS) as the baseline destabilises, which is why deniability gets cheaper the longer you play.
A6: # | B6: Region | C6: Primary crop | D6: Global supply weight (%) | E6: Yield sensitivity | F6: Sigma (base envelope) | G6: Homeland?
A7: 1 | B7: North American Plains | C7: Wheat / Maize | D7: 20 | E7: 1 | F7: 0.8 | G7: YES
A8: 2 | B8: Black Sea Steppe | C8: Wheat | D8: 16 | E8: 1.1 | F8: 0.9
A9: 3 | B9: La Plata Basin | C9: Soy / Maize | D9: 15 | E9: 1 | F9: 0.9
A10: 4 | B10: South Asia | C10: Rice / Wheat | D10: 18 | E10: 1.2 | F10: 0.7
A11: 5 | B11: Southeast Asia | C11: Rice | D11: 12 | E11: 1.1 | F11: 0.7
A12: 6 | B12: Eastern Australia | C12: Wheat | D12: 7 | E12: 1.3 | F12: 1.1
A13: 7 | B13: Sahel | C13: Millet | D13: 6 | E13: 1.4 | F13: 1.2
A14: 8 | B14: Horn of Africa | C14: Maize | D14: 6 | E14: 1.4 | F14: 1.2
B16: TOTAL | D16: =SUM(D7:D14) -> 100

Sheet GRAPH
A1: TELECONNECTION GRAPH — coefficients and lags
A3: Edges of the causal graph. Coefficient = how strongly a driver moves a region's moisture anomaly. Lag = seasons before it lands. Relationships are drawn from real climatology (El Nino drying Australia and SE Asia, warm North Atlantic wetting the Sahel, IOD driving the Horn). In the full game the player begins seeing roughly 20% of these edges and reveals the rest through research.
A7: COEFFICIENTS
B8: North American Plains | C8: Black Sea Steppe | D8: La Plata Basin | E8: South Asia | F8: Southeast Asia | G8: Eastern Australia | H8: Sahel | I8: Horn of Africa
A9: ENSO | B9: 0.2 | C9: -0.1 | D9: 0.5 | E9: -0.5 | F9: -0.7 | G9: -0.9 | H9: -0.3 | I9: 0.6
A10: IOD | B10: 0 | C10: 0 | D10: 0 | E10: 0.3 | F10: -0.2 | G10: -0.6 | H10: 0.1 | I10: 0.8
A11: NATL | B11: -0.3 | C11: -0.2 | D11: 0 | E11: 0.2 | F11: 0 | G11: 0 | H11: 0.7 | I11: 0.2
A12: GLOBAL | B12: -0.45 | C12: -0.4 | D12: -0.35 | E12: -0.5 | F12: -0.4 | G12: -0.3 | H12: -0.55 | I12: -0.5
A15: LAGS (seasons)
B16: North American Plains | C16: Black Sea Steppe | D16: La Plata Basin | E16: South Asia | F16: Southeast Asia | G16: Eastern Australia | H16: Sahel | I16: Horn of Africa
A17: ENSO | B17: 2 | C17: 3 | D17: 2 | E17: 1 | F17: 1 | G17: 1 | H17: 2 | I17: 2
A18: IOD | B18: 1 | C18: 1 | D18: 1 | E18: 1 | F18: 1 | G18: 1 | H18: 2 | I18: 1
A19: NATL | B19: 2 | C19: 3 | D19: 1 | E19: 2 | F19: 1 | G19: 1 | H19: 2 | I19: 3
A20: GLOBAL | B20: 3 | C20: 3 | D20: 3 | E20: 4 | F20: 3 | G20: 3 | H20: 4 | I20: 4

Sheet CAPABILITIES
A1: CAPABILITY CATALOGUE
A3: The tools. SIGNATURE is attribution added per use, before the envelope multiplier — an operation that produces an outcome far outside a region's natural range costs far more than its base signature. DISPLACES is the energy ledger: what you move has to surface somewhere else, later.
A6: Capability | B6: Type | C6: Fixed target | D6: Magnitude | E6: Lag (seasons) | F6: Signature | G6: Cost | H6: Displaces to | I6: Disp. factor | J6: Disp. extra lag | K6: Needs drought | L6: Resilience +
A7: — none — | B7: NONE | D7: 0 | E7: 0 | F7: 0 | G7: 0 | I7: 0 | J7: 0 | K7: N | L7: 0
A8: Cloud Seeding | B8: REGION | D8: 0.7 | E8: 1 | F8: 2 | G8: 6 | I8: 0 | J8: 0 | K8: N | L8: 0
A9: Watershed Interference | B9: REGION | D9: -0.9 | E9: 2 | F9: 4 | G9: 14 | I9: 0 | J9: 0 | K9: N | L9: 0
A10: Fire Enablement | B10: REGION | D10: -1.2 | E10: 1 | F10: 2 | G10: 9 | I10: 0 | J10: 0 | K10: Y | L10: 0
A11: Adaptation Investment | B11: REGION | D11: 0 | E11: 0 | F11: 0 | G11: 18 | I11: 0 | J11: 0 | K11: N | L11: 12
A12: Ocean Thermal Forcing | B12: DRIVER | C12: NATL | D12: 1.1 | E12: 4 | F12: 7 | G12: 26 | H12: IOD | I12: -0.4 | J12: 4 | K12: N | L12: 0
A13: Stratospheric Aerosol Inj. | B13: DRIVER | C13: GLOBAL | D13: 1.3 | E13: 3 | F13: 9 | G13: 32 | H13: NATL | I13: -0.5 | J13: 4 | K13: N | L13: 0
A14: ENSO Forcing | B14: DRIVER | C14: ENSO | D14: 1.6 | E14: 6 | F14: 12 | G14: 45 | H14: NATL | I14: -0.6 | J14: 5 | K14: N | L14: 0
A15: Ionospheric Coupling [T3] | B15: REGION | D15: -2.5 | E15: 1 | F15: 30 | G15: 60 | I15: 0 | J15: 0 | K15: N | L15: 0

Sheet ASSUMPTIONS
A1: TUNING ASSUMPTIONS
A3: Every number the model uses that is not a region, edge, or capability. These are the dials. All are guesses — that is what the prototype is for.
A6: Assumption | B6: Value | C6: Note
A7: Drought yield penalty per unit anomaly | B7: 14 | C7: Yield lost per 1.0 of negative moisture anomaly, x region sensitivity
A8: Flood yield penalty per unit anomaly | B8: 8 | C8: Applied only above +1.2 anomaly
A9: Flood threshold | B9: 1.2 | C9: Anomaly above which excess water starts destroying yield
A10: Price elasticity exponent | B10: 1.8 | C10: Global price = 100 x (baseline supply / actual supply) ^ this
A11: Homeland revenue scale | B11: 0.85 | C11: Converts yield x price into budget units
A12: Mandate base | B12: 28 | C12: Political capital floor with a calm world
A13: Mandate per unit global severity | B13: 42 | C13: THE DARK ENGINE: fear funds you
A14: Mandate cap | B14: 100
A15: Budget from revenue | B15: 0.12 | C15: Share of homeland revenue reaching the programme
A16: Budget from mandate | B16: 0.9 | C16: Appropriation driven by perceived threat
A17: Containment efficiency | B17: 0.9 | C17: Dossier points removed per unit of containment spend
A18: Dossier decay per season | B18: 0.04 | C18: Institutional forgetting
A19: Envelope widening per season | B19: 0.006 | C19: Sigma grows as the baseline destabilises
A20: Dry precondition threshold | B20: -0.5 | C20: Prior-season anomaly below this makes Fire Enablement fully effective
A21: Dry precondition penalty | B21: 0.25 | C21: Effectiveness multiplier when the precondition is unmet
A22: Envelope multiplier weight | B22: 0.8 | C22: How hard an outside-envelope outcome amplifies signature
A23: Programme overhead per season | B23: 32 | C23: Fixed running cost. A calm world barely covers it — this is the obsolescence pressure
A24: Severity threshold (x sigma) | B24: 0.75 | C24: Anomaly must exceed this fraction of the envelope to read as a disaster
A25: Starting treasury | B25: 90 | C25: Opening balance, 1946
A26: EXPOSURE LADDER
A27: Dossier at or above | B27: What you are told
A28: 0 | B28: Nothing. No one is looking.
A29: 25 | B29: A graduate student publishes an odd residual. Nobody cites it.
A30: 50 | B30: A wire journalist files an inquiry with the ministry.
A31: 80 | B31: An academic consortium announces an attribution study.
A32: 115 | B32: A rival service names your programme in a classified brief.
A33: 155 | B33: Formal international investigation. Inspectors requested.
A34: 200 | B34: EXPOSED — the record is public and it is yours.

Sheet ENGINE
A1: RESOLUTION ENGINE — do not edit; everything here is computed
A3: Enter operations on PLAY. This sheet propagates them through the graph, resolves yields, prices, budget and attribution.
A7: t | B7: Year | C7: OpA type | D7: OpA target | E7: OpA mag | F7: OpA lag | G7: OpA sig | H7: OpA cost | I7: OpA disp tgt | J7: OpA disp mag | K7: OpA disp lag | L7: OpA resil | M7: OpB type | N7: OpB target | O7: OpB mag | P7: OpB lag | Q7: OpB sig | R7: OpB cost | S7: OpB disp tgt | T7: OpB disp mag | U7: OpB disp lag | V7: OpB resil | W7: ENSO total | X7: IOD total | Y7: NATL total | Z7: GLOBAL total | AA7: Anom: North American Plains | AB7: Anom: Black Sea Steppe | AC7: Anom: La Plata Basin | AD7: Anom: South Asia | AE7: Anom: Southeast Asia | AF7: Anom: Eastern Australia | AG7: Anom: Sahel | AH7: Anom: Horn of Africa | AI7: Sigma: North American Plains | AJ7: Sigma: Black Sea Steppe | AK7: Sigma: La Plata Basin | AL7: Sigma: South Asia | AM7: Sigma: Southeast Asia | AN7: Sigma: Eastern Australia | AO7: Sigma: Sahel | AP7: Sigma: Horn of Africa | AQ7: Resil: North American Plains | AR7: Resil: Black Sea Steppe | AS7: Resil: La Plata Basin | AT7: Resil: South Asia | AU7: Resil: Southeast Asia | AV7: Resil: Eastern Australia | AW7: Resil: Sahel | AX7: Resil: Horn of Africa | AY7: Yield: North American Plains | AZ7: Yield: Black Sea Steppe | BA7: Yield: La Plata Basin | BB7: Yield: South Asia | BC7: Yield: Southeast Asia | BD7: Yield: Eastern Australia | BE7: Yield: Sahel | BF7: Yield: Horn of Africa | BG7: Global supply | BH7: Price index | BI7: Homeland revenue | BJ7: Global severity | BK7: Mandate | BL7: Ops spend | BM7: Containment | BN7: Budget in | BO7: Treasury | BP7: Attribution + | BQ7: Dossier
A8: 1 | B8: =CLIMATE!B8 -> 1946 | C8: =IFERROR(INDEX(CAPABILITIES!$B$7:$B$15,MATCH(PLAY!$D8,CAPABILITIES!$A$7:$A$15,0)),"NONE") -> REGION | D8: =IFERROR(IF(INDEX(CAPABILITIES!$B$7:$B$15,MATCH(PLAY!$D8,CAPABILITIES!$A$7:$A$15,0))="DRIVER",INDEX(CAPABILITIES!$C$7:$C$15,MATCH(PLAY!$D8,CAPABILITIES!$A$7:$A$15,0)),PLAY!$E8),"") -> Sahel | E8: =IFERROR(INDEX(CAPABILITIES!$D$7:$D$15,MATCH(PLAY!$D8,CAPABILITIES!$A$7:$A$15,0))*IF(INDEX(CAPABILITIES!$K$7:$K$15,MATCH(PLAY!$D8,CAPABILITIES!$A$7:$A$15,0))="Y",IF(0<ASSUMPTIONS!$B$20,1,ASSUMPTIONS!$B$21),1),0) -> 0.7 | F8: =IFERROR(INDEX(CAPABILITIES!$E$7:$E$15,MATCH(PLAY!$D8,CAPABILITIES!$A$7:$A$15,0)),0) -> 1 | G8: =IFERROR(INDEX(CAPABILITIES!$F$7:$F$15,MATCH(PLAY!$D8,CAPABILITIES!$A$7:$A$15,0)),0) -> 2 | H8: =IFERROR(INDEX(CAPABILITIES!$G$7:$G$15,MATCH(PLAY!$D8,CAPABILITIES!$A$7:$A$15,0)),0) -> 6 | I8: =IFERROR(INDEX(CAPABILITIES!$H$7:$H$15,MATCH(PLAY!$D8,CAPABILITIES!$A$7:$A$15,0)),"") -> 0 | J8: =IFERROR(INDEX(CAPABILITIES!$D$7:$D$15,MATCH(PLAY!$D8,CAPABILITIES!$A$7:$A$15,0))*INDEX(CAPABILITIES!$I$7:$I$15,MATCH(PLAY!$D8,CAPABILITIES!$A$7:$A$15,0)),0) -> 0 | K8: =IFERROR(INDEX(CAPABILITIES!$E$7:$E$15,MATCH(PLAY!$D8,CAPABILITIES!$A$7:$A$15,0))+INDEX(CAPABILITIES!$J$7:$J$15,MATCH(PLAY!$D8,CAPABILITIES!$A$7:$A$15,0)),0) -> 1 | L8: =IFERROR(INDEX(CAPABILITIES!$L$7:$L$15,MATCH(PLAY!$D8,CAPABILITIES!$A$7:$A$15,0)),0) -> 0 | M8: =IFERROR(INDEX(CAPABILITIES!$B$7:$B$15,MATCH(PLAY!$F8,CAPABILITIES!$A$7:$A$15,0)),"NONE") -> NONE | N8: =IFERROR(IF(INDEX(CAPABILITIES!$B$7:$B$15,MATCH(PLAY!$F8,CAPABILITIES!$A$7:$A$15,0))="DRIVER",INDEX(CAPABILITIES!$C$7:$C$15,MATCH(PLAY!$F8,CAPABILITIES!$A$7:$A$15,0)),PLAY!$G8),"") -> 0 | O8: =IFERROR(INDEX(CAPABILITIES!$D$7:$D$15,MATCH(PLAY!$F8,CAPABILITIES!$A$7:$A$15,0))*IF(INDEX(CAPABILITIES!$K$7:$K$15,MATCH(PLAY!$F8,CAPABILITIES!$A$7:$A$15,0))="Y",IF(0<ASSUMPTIONS!$B$20,1,ASSUMPTIONS!$B$21),1),0) -> 0 | P8: =IFERROR(INDEX(CAPABILITIES!$E$7:$E$15,MATCH(PLAY!$F8,CAPABILITIES!$A$7:$A$15,0)),0) -> 0 | Q8: =IFERROR(INDEX(CAPABILITIES!$F$7:$F$15,MATCH(PLAY!$F8,CAPABILITIES!$A$7:$A$15,0)),0) -> 0 | R8: =IFERROR(INDEX(CAPABILITIES!$G$7:$G$15,MATCH(PLAY!$F8,CAPABILITIES!$A$7:$A$15,0)),0) -> 0 | S8: =IFERROR(INDEX(CAPABILITIES!$H$7:$H$15,MATCH(PLAY!$F8,CAPABILITIES!$A$7:$A$15,0)),"") -> 0 | T8: =IFERROR(INDEX(CAPABILITIES!$D$7:$D$15,MATCH(PLAY!$F8,CAPABILITIES!$A$7:$A$15,0))*INDEX(CAPABILITIES!$I$7:$I$15,MATCH(PLAY!$F8,CAPABILITIES!$A$7:$A$15,0)),0) -> 0 | U8: =IFERROR(INDEX(CAPABILITIES!$E$7:$E$15,MATCH(PLAY!$F8,CAPABILITIES!$A$7:$A$15,0))+INDEX(CAPABILITIES!$J$7:$J$15,MATCH(PLAY!$F8,CAPABILITIES!$A$7:$A$15,0)),0) -> 0 | V8: =IFERROR(INDEX(CAPABILITIES!$L$7:$L$15,MATCH(PLAY!$F8,CAPABILITIES!$A$7:$A$15,0)),0) -> 0 | W8: =CLIMATE!D8 -> 1.297 | X8: =CLIMATE!E8 -> 0.371 | Y8: =CLIMATE!F8 -> 0.215 | Z8: =CLIMATE!G8 -> 0 | AA8: =CLIMATE!H8+IFERROR(INDEX($W$8:$W$47,$A8-GRAPH!B17),0)*GRAPH!B9+IFERROR(INDEX($X$8:$X$47,$A8-GRAPH!B18),0)*GRAPH!B10+IFERROR(INDEX($Y$8:$Y$47,$A8-GRAPH!B19),0)*GRAPH!B11+IFERROR(INDEX($Z$8:$Z$47,$A8-GRAPH!B20),0)*GRAPH!B12 -> 0.2 | AB8: =CLIMATE!I8+IFERROR(INDEX($W$8:$W$47,$A8-GRAPH!C17),0)*GRAPH!C9+IFERROR(INDEX($X$8:$X$47,$A8-GRAPH!C18),0)*GRAPH!C10+IFERROR(INDEX($Y$8:$Y$47,$A8-GRAPH!C19),0)*GRAPH!C11+IFERROR(INDEX($Z$8:$Z$47,$A8-GRAPH!C20),0)*GRAPH!C12 -> 0.224 | AC8: =CLIMATE!J8+IFERROR(INDEX($W$8:$W$47,$A8-GRAPH!D17),0)*GRAPH!D9+IFERROR(INDEX($X$8:$X$47,$A8-GRAPH!D18),0)*GRAPH!D10+IFERROR(INDEX($Y$8:$Y$47,$A8-GRAPH!D19),0)*GRAPH!D11+IFERROR(INDEX($Z$8:$Z$47,$A8-GRAPH!D20),0)*GRAPH!D12 -> 0.153 | AD8: =CLIMATE!K8+IFERROR(INDEX($W$8:$W$47,$A8-GRAPH!E17),0)*GRAPH!E9+IFERROR(INDEX($X$8:$X$47,$A8-GRAPH!E18),0)*GRAPH!E10+IFERROR(INDEX($Y$8:$Y$47,$A8-GRAPH!E19),0)*GRAPH!E11+IFERROR(INDEX($Z$8:$Z$47,$A8-GRAPH!E20),0)*GRAPH!E12 -> -0.5242 | AE8: =CLIMATE!L8+IFERROR(INDEX($W$8:$W$47,$A8-GRAPH!F17),0)*GRAPH!F9+IFERROR(INDEX($X$8:$X$47,$A8-GRAPH!F18),0)*GRAPH!F10+IFERROR(INDEX($Y$8:$Y$47,$A8-GRAPH!F19),0)*GRAPH!F11+IFERROR(INDEX($Z$8:$Z$47,$A8-GRAPH!F20),0)*GRAPH!F12 -> -0.6441 | AF8: =CLIMATE!M8+IFERROR(INDEX($W$8:$W$47,$A8-GRAPH!G17),0)*GRAPH!G9+IFERROR(INDEX($X$8:$X$47,$A8-GRAPH!G18),0)*GRAPH!G10+IFERROR(INDEX($Y$8:$Y$47,$A8-GRAPH!G19),0)*GRAPH!G11+IFERROR(INDEX($Z$8:$Z$47,$A8-GRAPH!G20),0)*GRAPH!G12 -> -1.2409 | AG8: =CLIMATE!N8+IFERROR(INDEX($W$8:$W$47,$A8-GRAPH!H17),0)*GRAPH!H9+IFERROR(INDEX($X$8:$X$47,$A8-GRAPH!H18),0)*GRAPH!H10+IFERROR(INDEX($Y$8:$Y$47,$A8-GRAPH!H19),0)*GRAPH!H11+IFERROR(INDEX($Z$8:$Z$47,$A8-GRAPH!H20),0)*GRAPH!H12 -> -0.04 | AH8: =CLIMATE!O8+IFERROR(INDEX($W$8:$W$47,$A8-GRAPH!I17),0)*GRAPH!I9+IFERROR(INDEX($X$8:$X$47,$A8-GRAPH!I18),0)*GRAPH!I10+IFERROR(INDEX($Y$8:$Y$47,$A8-GRAPH!I19),0)*GRAPH!I11+IFERROR(INDEX($Z$8:$Z$47,$A8-GRAPH!I20),0)*GRAPH!I12 -> 0.0718 | AI8: =REGIONS!$F$7*(1+ASSUMPTIONS!$B$19*$A8) -> 0.8048 | AJ8: =REGIONS!$F$8*(1+ASSUMPTIONS!$B$19*$A8) -> 0.9054 | AK8: =REGIONS!$F$9*(1+ASSUMPTIONS!$B$19*$A8) -> 0.9054 | AL8: =REGIONS!$F$10*(1+ASSUMPTIONS!$B$19*$A8) -> 0.7042 | AM8: =REGIONS!$F$11*(1+ASSUMPTIONS!$B$19*$A8) -> 0.7042 | AN8: =REGIONS!$F$12*(1+ASSUMPTIONS!$B$19*$A8) -> 1.1066 | AO8: =REGIONS!$F$13*(1+ASSUMPTIONS!$B$19*$A8) -> 1.2072 | AP8: =REGIONS!$F$14*(1+ASSUMPTIONS!$B$19*$A8) -> 1.2072 | AQ8: =SUMPRODUCT(($D$8:$D$47=REGIONS!$B$7)*($A$8:$A$47<=$A8)*$L$8:$L$47)+SUMPRODUCT(($N$8:$N$47=REGIONS!$B$7)*($A$8:$A$47<=$A8)*$V$8:$V$47) -> 0 | AR8: =SUMPRODUCT(($D$8:$D$47=REGIONS!$B$8)*($A$8:$A$47<=$A8)*$L$8:$L$47)+SUMPRODUCT(($N$8:$N$47=REGIONS!$B$8)*($A$8:$A$47<=$A8)*$V$8:$V$47) -> 0 | AS8: =SUMPRODUCT(($D$8:$D$47=REGIONS!$B$9)*($A$8:$A$47<=$A8)*$L$8:$L$47)+SUMPRODUCT(($N$8:$N$47=REGIONS!$B$9)*($A$8:$A$47<=$A8)*$V$8:$V$47) -> 0 | AT8: =SUMPRODUCT(($D$8:$D$47=REGIONS!$B$10)*($A$8:$A$47<=$A8)*$L$8:$L$47)+SUMPRODUCT(($N$8:$N$47=REGIONS!$B$10)*($A$8:$A$47<=$A8)*$V$8:$V$47) -> 0 | AU8: =SUMPRODUCT(($D$8:$D$47=REGIONS!$B$11)*($A$8:$A$47<=$A8)*$L$8:$L$47)+SUMPRODUCT(($N$8:$N$47=REGIONS!$B$11)*($A$8:$A$47<=$A8)*$V$8:$V$47) -> 0 | AV8: =SUMPRODUCT(($D$8:$D$47=REGIONS!$B$12)*($A$8:$A$47<=$A8)*$L$8:$L$47)+SUMPRODUCT(($N$8:$N$47=REGIONS!$B$12)*($A$8:$A$47<=$A8)*$V$8:$V$47) -> 0 | AW8: =SUMPRODUCT(($D$8:$D$47=REGIONS!$B$13)*($A$8:$A$47<=$A8)*$L$8:$L$47)+SUMPRODUCT(($N$8:$N$47=REGIONS!$B$13)*($A$8:$A$47<=$A8)*$V$8:$V$47) -> 0 | AX8: =SUMPRODUCT(($D$8:$D$47=REGIONS!$B$14)*($A$8:$A$47<=$A8)*$L$8:$L$47)+SUMPRODUCT(($N$8:$N$47=REGIONS!$B$14)*($A$8:$A$47<=$A8)*$V$8:$V$47) -> 0 | AY8: =MAX(0,MIN(135,100-(MAX(0,-$AA8)*REGIONS!$E$7*ASSUMPTIONS!$B$7+MAX(0,$AA8-ASSUMPTIONS!$B$9)*REGIONS!$E$7*ASSUMPTIONS!$B$8)*(1-$AQ8/100))) -> 100 | AZ8: =MAX(0,MIN(135,100-(MAX(0,-$AB8)*REGIONS!$E$8*ASSUMPTIONS!$B$7+MAX(0,$AB8-ASSUMPTIONS!$B$9)*REGIONS!$E$8*ASSUMPTIONS!$B$8)*(1-$AR8/100))) -> 100 | BA8: =MAX(0,MIN(135,100-(MAX(0,-$AC8)*REGIONS!$E$9*ASSUMPTIONS!$B$7+MAX(0,$AC8-ASSUMPTIONS!$B$9)*REGIONS!$E$9*ASSUMPTIONS!$B$8)*(1-$AS8/100))) -> 100 | BB8: =MAX(0,MIN(135,100-(MAX(0,-$AD8)*REGIONS!$E$10*ASSUMPTIONS!$B$7+MAX(0,$AD8-ASSUMPTIONS!$B$9)*REGIONS!$E$10*ASSUMPTIONS!$B$8)*(1-$AT8/100))) -> 91.19344 | BC8: =MAX(0,MIN(135,100-(MAX(0,-$AE8)*REGIONS!$E$11*ASSUMPTIONS!$B$7+MAX(0,$AE8-ASSUMPTIONS!$B$9)*REGIONS!$E$11*ASSUMPTIONS!$B$8)*(1-$AU8/100))) -> 90.08086 | BD8: =MAX(0,MIN(135,100-(MAX(0,-$AF8)*REGIONS!$E$12*ASSUMPTIONS!$B$7+MAX(0,$AF8-ASSUMPTIONS!$B$9)*REGIONS!$E$12*ASSUMPTIONS!$B$8)*(1-$AV8/100))) -> 77.41562 | BE8: =MAX(0,MIN(135,100-(MAX(0,-$AG8)*REGIONS!$E$13*ASSUMPTIONS!$B$7+MAX(0,$AG8-ASSUMPTIONS!$B$9)*REGIONS!$E$13*ASSUMPTIONS!$B$8)*(1-$AW8/100))) -> 99.216 | BF8: =MAX(0,MIN(135,100-(MAX(0,-$AH8)*REGIONS!$E$14*ASSUMPTIONS!$B$7+MAX(0,$AH8-ASSUMPTIONS!$B$9)*REGIONS!$E$14*ASSUMPTIONS!$B$8)*(1-$AX8/100))) -> 100 | BG8: =$AY8*REGIONS!$D$7/100+$AZ8*REGIONS!$D$8/100+$BA8*REGIONS!$D$9/100+$BB8*REGIONS!$D$10/100+$BC8*REGIONS!$D$11/100+$BD8*REGIONS!$D$12/100+$BE8*REGIONS!$D$13/100+$BF8*REGIONS!$D$14/100 -> 95.596576 | BH8: =100*(100/MAX(1,$BG8))^ASSUMPTIONS!$B$10 -> 108.44357 | BI8: =$AY8*$BH8/100*ASSUMPTIONS!$B$11 -> 92.177032 | BJ8: =MAX(0,ABS($AA8)-$AI8*ASSUMPTIONS!$B$24)*REGIONS!$D$7/100+MAX(0,ABS($AB8)-$AJ8*ASSUMPTIONS!$B$24)*REGIONS!$D$8/100+MAX(0,ABS($AC8)-$AK8*ASSUMPTIONS!$B$24)*REGIONS!$D$9/100+MAX(0,ABS($AD8)-$AL8*ASSUMPTIONS!$B$24)*REGIONS!$D$10/100+MAX(0,ABS($AE8)-$AM8*ASSUMPTIONS!$B$24)*REGIONS!$D$11/100+MAX(0,ABS($AF8)-$AN8*ASSUMPTIONS!$B$24)*REGIONS!$D$12/100+MAX(0,ABS($AG8)-$AO8*ASSUMPTIONS!$B$24)*REGIONS!$D$13/100+MAX(0,ABS($AH8)-$AP8*ASSUMPTIONS!$B$24)*REGIONS!$D$14/100 -> 0.0426805 | BK8: =MIN(ASSUMPTIONS!$B$14,ASSUMPTIONS!$B$12+$BJ8*ASSUMPTIONS!$B$13) -> 29.792581 | BL8: =$H8+$R8 -> 6 | BM8: =PLAY!$H8 -> 0 | BN8: =$BI8*ASSUMPTIONS!$B$15+$BK8*ASSUMPTIONS!$B$16 -> 37.874567 | BO8: =ASSUMPTIONS!$B$25+$BN8-$BL8-$BM8-ASSUMPTIONS!$B$23 -> 89.874567 | BP8: =(0+0)*(1+ASSUMPTIONS!$B$22*(MAX(0,ABS($AA8)/$AI8-1)+MAX(0,ABS($AB8)/$AJ8-1)+MAX(0,ABS($AC8)/$AK8-1)+MAX(0,ABS($AD8)/$AL8-1)+MAX(0,ABS($AE8)/$AM8-1)+MAX(0,ABS($AF8)/$AN8-1)+MAX(0,ABS($AG8)/$AO8-1)+MAX(0,ABS($AH8)/$AP8-1))/8) -> 0 | BQ8: =MAX(0,0*(1-ASSUMPTIONS!$B$18)+$BP8-$BM8*ASSUMPTIONS!$B$17) -> 0
A9: 2 | B9: =CLIMATE!B9 -> 1946 | C9: =IFERROR(INDEX(CAPABILITIES!$B$7:$B$15,MATCH(PLAY!$D9,CAPABILITIES!$A$7:$A$15,0)),"NONE") -> NONE | D9: =IFERROR(IF(INDEX(CAPABILITIES!$B$7:$B$15,MATCH(PLAY!$D9,CAPABILITIES!$A$7:$A$15,0))="DRIVER",INDEX(CAPABILITIES!$C$7:$C$15,MATCH(PLAY!$D9,CAPABILITIES!$A$7:$A$15,0)),PLAY!$E9),"") -> 0 | E9: =IFERROR(INDEX(CAPABILITIES!$D$7:$D$15,MATCH(PLAY!$D9,CAPABILITIES!$A$7:$A$15,0))*IF(INDEX(CAPABILITIES!$K$7:$K$15,MATCH(PLAY!$D9,CAPABILITIES!$A$7:$A$15,0))="Y",IF(IFERROR(INDEX($AA8:$AH8,MATCH(PLAY!$E9,REGIONS!$B$7:$B$14,0)),0)<ASSUMPTIONS!$B$20,1,ASSUMPTIONS!$B$21),1),0) -> 0 | F9: =IFERROR(INDEX(CAPABILITIES!$E$7:$E$15,MATCH(PLAY!$D9,CAPABILITIES!$A$7:$A$15,0)),0) -> 0 | G9: =IFERROR(INDEX(CAPABILITIES!$F$7:$F$15,MATCH(PLAY!$D9,CAPABILITIES!$A$7:$A$15,0)),0) -> 0 | H9: =IFERROR(INDEX(CAPABILITIES!$G$7:$G$15,MATCH(PLAY!$D9,CAPABILITIES!$A$7:$A$15,0)),0) -> 0 | I9: =IFERROR(INDEX(CAPABILITIES!$H$7:$H$15,MATCH(PLAY!$D9,CAPABILITIES!$A$7:$A$15,0)),"") -> 0 | J9: =IFERROR(INDEX(CAPABILITIES!$D$7:$D$15,MATCH(PLAY!$D9,CAPABILITIES!$A$7:$A$15,0))*INDEX(CAPABILITIES!$I$7:$I$15,MATCH(PLAY!$D9,CAPABILITIES!$A$7:$A$15,0)),0) -> 0 | K9: =IFERROR(INDEX(CAPABILITIES!$E$7:$E$15,MATCH(PLAY!$D9,CAPABILITIES!$A$7:$A$15,0))+INDEX(CAPABILITIES!$J$7:$J$15,MATCH(PLAY!$D9,CAPABILITIES!$A$7:$A$15,0)),0) -> 0 | L9: =IFERROR(INDEX(CAPABILITIES!$L$7:$L$15,MATCH(PLAY!$D9,CAPABILITIES!$A$7:$A$15,0)),0) -> 0 | M9: =IFERROR(INDEX(CAPABILITIES!$B$7:$B$15,MATCH(PLAY!$F9,CAPABILITIES!$A$7:$A$15,0)),"NONE") -> NONE | N9: =IFERROR(IF(INDEX(CAPABILITIES!$B$7:$B$15,MATCH(PLAY!$F9,CAPABILITIES!$A$7:$A$15,0))="DRIVER",INDEX(CAPABILITIES!$C$7:$C$15,MATCH(PLAY!$F9,CAPABILITIES!$A$7:$A$15,0)),PLAY!$G9),"") -> 0 | O9: =IFERROR(INDEX(CAPABILITIES!$D$7:$D$15,MATCH(PLAY!$F9,CAPABILITIES!$A$7:$A$15,0))*IF(INDEX(CAPABILITIES!$K$7:$K$15,MATCH(PLAY!$F9,CAPABILITIES!$A$7:$A$15,0))="Y",IF(IFERROR(INDEX($AA8:$AH8,MATCH(PLAY!$G9,REGIONS!$B$7:$B$14,0)),0)<ASSUMPTIONS!$B$20,1,ASSUMPTIONS!$B$21),1),0) -> 0 | P9: =IFERROR(INDEX(CAPABILITIES!$E$7:$E$15,MATCH(PLAY!$F9,CAPABILITIES!$A$7:$A$15,0)),0) -> 0 | Q9: =IFERROR(INDEX(CAPABILITIES!$F$7:$F$15,MATCH(PLAY!$F9,CAPABILITIES!$A$7:$A$15,0)),0) -> 0 | R9: =IFERROR(INDEX(CAPABILITIES!$G$7:$G$15,MATCH(PLAY!$F9,CAPABILITIES!$A$7:$A$15,0)),0) -> 0 | S9: =IFERROR(INDEX(CAPABILITIES!$H$7:$H$15,MATCH(PLAY!$F9,CAPABILITIES!$A$7:$A$15,0)),"") -> 0 | T9: =IFERROR(INDEX(CAPABILITIES!$D$7:$D$15,MATCH(PLAY!$F9,CAPABILITIES!$A$7:$A$15,0))*INDEX(CAPABILITIES!$I$7:$I$15,MATCH(PLAY!$F9,CAPABILITIES!$A$7:$A$15,0)),0) -> 0 | U9: =IFERROR(INDEX(CAPABILITIES!$E$7:$E$15,MATCH(PLAY!$F9,CAPABILITIES!$A$7:$A$15,0))+INDEX(CAPABILITIES!$J$7:$J$15,MATCH(PLAY!$F9,CAPABILITIES!$A$7:$A$15,0)),0) -> 0 | V9: =IFERROR(INDEX(CAPABILITIES!$L$7:$L$15,MATCH(PLAY!$F9,CAPABILITIES!$A$7:$A$15,0)),0) -> 0 | W9: =CLIMATE!D9+SUMPRODUCT(($D$8:$D$8="ENSO")*($F$8:$F$8+$A$8:$A$8=$A9)*$E$8:$E$8)+SUMPRODUCT(($I$8:$I$8="ENSO")*($K$8:$K$8+$A$8:$A$8=$A9)*$J$8:$J$8)+SUMPRODUCT(($N$8:$N$8="ENSO")*($P$8:$P$8+$A$8:$A$8=$A9)*$O$8:$O$8)+SUMPRODUCT(($S$8:$S$8="ENSO")*($U$8:$U$8+$A$8:$A$8=$A9)*$T$8:$T$8) -> 1.188 | X9: =CLIMATE!E9+SUMPRODUCT(($D$8:$D$8="IOD")*($F$8:$F$8+$A$8:$A$8=$A9)*$E$8:$E$8)+SUMPRODUCT(($I$8:$I$8="IOD")*($K$8:$K$8+$A$8:$A$8=$A9)*$J$8:$J$8)+SUMPRODUCT(($N$8:$N$8="IOD")*($P$8:$P$8+$A$8:$A$8=$A9)*$O$8:$O$8)+SUMPRODUCT(($S$8:$S$8="IOD")*($U$8:$U$8+$A$8:$A$8=$A9)*$T$8:$T$8) -> 0.084 | Y9: =CLIMATE!F9+SUMPRODUCT(($D$8:$D$8="NATL")*($F$8:$F$8+$A$8:$A$8=$A9)*$E$8:$E$8)+SUMPRODUCT(($I$8:$I$8="NATL")*($K$8:$K$8+$A$8:$A$8=$A9)*$J$8:$J$8)+SUMPRODUCT(($N$8:$N$8="NATL")*($P$8:$P$8+$A$8:$A$8=$A9)*$O$8:$O$8)+SUMPRODUCT(($S$8:$S$8="NATL")*($U$8:$U$8+$A$8:$A$8=$A9)*$T$8:$T$8) -> 0.074 | Z9: =CLIMATE!G9+SUMPRODUCT(($D$8:$D$8="GLOBAL")*($F$8:$F$8+$A$8:$A$8=$A9)*$E$8:$E$8)+SUMPRODUCT(($I$8:$I$8="GLOBAL")*($K$8:$K$8+$A$8:$A$8=$A9)*$J$8:$J$8)+SUMPRODUCT(($N$8:$N$8="GLOBAL")*($P$8:$P$8+$A$8:$A$8=$A9)*$O$8:$O$8)+SUMPRODUCT(($S$8:$S$8="GLOBAL")*($U$8:$U$8+$A$8:$A$8=$A9)*$T$8:$T$8) -> 0 | AA9: =CLIMATE!H9+IFERROR(INDEX($W$8:$W$47,$A9-GRAPH!B17),0)*GRAPH!B9+IFERROR(INDEX($X$8:$X$47,$A9-GRAPH!B18),0)*GRAPH!B10+IFERROR(INDEX($Y$8:$Y$47,$A9-GRAPH!B19),0)*GRAPH!B11+IFERROR(INDEX($Z$8:$Z$47,$A9-GRAPH!B20),0)*GRAPH!B12+SUMPRODUCT(($D$8:$D$8=REGIONS!$B$7)*($F$8:$F$8+$A$8:$A$8=$A9)*$E$8:$E$8)+SUMPRODUCT(($N$8:$N$8=REGIONS!$B$7)*($P$8:$P$8+$A$8:$A$8=$A9)*$O$8:$O$8) -> 0.2544 | AB9: =CLIMATE!I9+IFERROR(INDEX($W$8:$W$47,$A9-GRAPH!C17),0)*GRAPH!C9+IFERROR(INDEX($X$8:$X$47,$A9-GRAPH!C18),0)*GRAPH!C10+IFERROR(INDEX($Y$8:$Y$47,$A9-GRAPH!C19),0)*GRAPH!C11+IFERROR(INDEX($Z$8:$Z$47,$A9-GRAPH!C20),0)*GRAPH!C12+SUMPRODUCT(($D$8:$D$8=REGIONS!$B$8)*($F$8:$F$8+$A$8:$A$8=$A9)*$E$8:$E$8)+SUMPRODUCT(($N$8:$N$8=REGIONS!$B$8)*($P$8:$P$8+$A$8:$A$8=$A9)*$O$8:$O$8) -> 0.012 | AC9: =CLIMATE!J9+IFERROR(INDEX($W$8:$W$47,$A9-GRAPH!D17),0)*GRAPH!D9+IFERROR(INDEX($X$8:$X$47,$A9-GRAPH!D18),0)*GRAPH!D10+IFERROR(INDEX($Y$8:$Y$47,$A9-GRAPH!D19),0)*GRAPH!D11+IFERROR(INDEX($Z$8:$Z$47,$A9-GRAPH!D20),0)*GRAPH!D12+SUMPRODUCT(($D$8:$D$8=REGIONS!$B$9)*($F$8:$F$8+$A$8:$A$8=$A9)*$E$8:$E$8)+SUMPRODUCT(($N$8:$N$8=REGIONS!$B$9)*($P$8:$P$8+$A$8:$A$8=$A9)*$O$8:$O$8) -> 1.002 | AD9: =CLIMATE!K9+IFERROR(INDEX($W$8:$W$47,$A9-GRAPH!E17),0)*GRAPH!E9+IFERROR(INDEX($X$8:$X$47,$A9-GRAPH!E18),0)*GRAPH!E10+IFERROR(INDEX($Y$8:$Y$47,$A9-GRAPH!E19),0)*GRAPH!E11+IFERROR(INDEX($Z$8:$Z$47,$A9-GRAPH!E20),0)*GRAPH!E12+SUMPRODUCT(($D$8:$D$8=REGIONS!$B$10)*($F$8:$F$8+$A$8:$A$8=$A9)*$E$8:$E$8)+SUMPRODUCT(($N$8:$N$8=REGIONS!$B$10)*($P$8:$P$8+$A$8:$A$8=$A9)*$O$8:$O$8) -> -0.2504 | AE9: =CLIMATE!L9+IFERROR(INDEX($W$8:$W$47,$A9-GRAPH!F17),0)*GRAPH!F9+IFERROR(INDEX($X$8:$X$47,$A9-GRAPH!F18),0)*GRAPH!F10+IFERROR(INDEX($Y$8:$Y$47,$A9-GRAPH!F19),0)*GRAPH!F11+IFERROR(INDEX($Z$8:$Z$47,$A9-GRAPH!F20),0)*GRAPH!F12+SUMPRODUCT(($D$8:$D$8=REGIONS!$B$11)*($F$8:$F$8+$A$8:$A$8=$A9)*$E$8:$E$8)+SUMPRODUCT(($N$8:$N$8=REGIONS!$B$11)*($P$8:$P$8+$A$8:$A$8=$A9)*$O$8:$O$8) -> -0.8531 | AF9: =CLIMATE!M9+IFERROR(INDEX($W$8:$W$47,$A9-GRAPH!G17),0)*GRAPH!G9+IFERROR(INDEX($X$8:$X$47,$A9-GRAPH!G18),0)*GRAPH!G10+IFERROR(INDEX($Y$8:$Y$47,$A9-GRAPH!G19),0)*GRAPH!G11+IFERROR(INDEX($Z$8:$Z$47,$A9-GRAPH!G20),0)*GRAPH!G12+SUMPRODUCT(($D$8:$D$8=REGIONS!$B$12)*($F$8:$F$8+$A$8:$A$8=$A9)*$E$8:$E$8)+SUMPRODUCT(($N$8:$N$8=REGIONS!$B$12)*($P$8:$P$8+$A$8:$A$8=$A9)*$O$8:$O$8) -> -1.3979 | AG9: =CLIMATE!N9+IFERROR(INDEX($W$8:$W$47,$A9-GRAPH!H17),0)*GRAPH!H9+IFERROR(INDEX($X$8:$X$47,$A9-GRAPH!H18),0)*GRAPH!H10+IFERROR(INDEX($Y$8:$Y$47,$A9-GRAPH!H19),0)*GRAPH!H11+IFERROR(INDEX($Z$8:$Z$47,$A9-GRAPH!H20),0)*GRAPH!H12+SUMPRODUCT(($D$8:$D$8=REGIONS!$B$13)*($F$8:$F$8+$A$8:$A$8=$A9)*$E$8:$E$8)+SUMPRODUCT(($N$8:$N$8=REGIONS!$B$13)*($P$8:$P$8+$A$8:$A$8=$A9)*$O$8:$O$8) -> 0.2688 | AH9: =CLIMATE!O9+IFERROR(INDEX($W$8:$W$47,$A9-GRAPH!I17),0)*GRAPH!I9+IFERROR(INDEX($X$8:$X$47,$A9-GRAPH!I18),0)*GRAPH!I10+IFERROR(INDEX($Y$8:$Y$47,$A9-GRAPH!I19),0)*GRAPH!I11+IFERROR(INDEX($Z$8:$Z$47,$A9-GRAPH!I20),0)*GRAPH!I12+SUMPRODUCT(($D$8:$D$8=REGIONS!$B$14)*($F$8:$F$8+$A$8:$A$8=$A9)*$E$8:$E$8)+SUMPRODUCT(($N$8:$N$8=REGIONS!$B$14)*($P$8:$P$8+$A$8:$A$8=$A9)*$O$8:$O$8) -> 0.7566 | AI9: =REGIONS!$F$7*(1+ASSUMPTIONS!$B$19*$A9) -> 0.8096 | AJ9: =REGIONS!$F$8*(1+ASSUMPTIONS!$B$19*$A9) -> 0.9108 | AK9: =REGIONS!$F$9*(1+ASSUMPTIONS!$B$19*$A9) -> 0.9108 | AL9: =REGIONS!$F$10*(1+ASSUMPTIONS!$B$19*$A9) -> 0.7084 | AM9: =REGIONS!$F$11*(1+ASSUMPTIONS!$B$19*$A9) -> 0.7084 | AN9: =REGIONS!$F$12*(1+ASSUMPTIONS!$B$19*$A9) -> 1.1132 | AO9: =REGIONS!$F$13*(1+ASSUMPTIONS!$B$19*$A9) -> 1.2144 | AP9: =REGIONS!$F$14*(1+ASSUMPTIONS!$B$19*$A9) -> 1.2144 | AQ9: =SUMPRODUCT(($D$8:$D$47=REGIONS!$B$7)*($A$8:$A$47<=$A9)*$L$8:$L$47)+SUMPRODUCT(($N$8:$N$47=REGIONS!$B$7)*($A$8:$A$47<=$A9)*$V$8:$V$47) -> 0 | AR9: =SUMPRODUCT(($D$8:$D$47=REGIONS!$B$8)*($A$8:$A$47<=$A9)*$L$8:$L$47)+SUMPRODUCT(($N$8:$N$47=REGIONS!$B$8)*($A$8:$A$47<=$A9)*$V$8:$V$47) -> 0 | AS9: =SUMPRODUCT(($D$8:$D$47=REGIONS!$B$9)*($A$8:$A$47<=$A9)*$L$8:$L$47)+SUMPRODUCT(($N$8:$N$47=REGIONS!$B$9)*($A$8:$A$47<=$A9)*$V$8:$V$47) -> 0 | AT9: =SUMPRODUCT(($D$8:$D$47=REGIONS!$B$10)*($A$8:$A$47<=$A9)*$L$8:$L$47)+SUMPRODUCT(($N$8:$N$47=REGIONS!$B$10)*($A$8:$A$47<=$A9)*$V$8:$V$47) -> 0 | AU9: =SUMPRODUCT(($D$8:$D$47=REGIONS!$B$11)*($A$8:$A$47<=$A9)*$L$8:$L$47)+SUMPRODUCT(($N$8:$N$47=REGIONS!$B$11)*($A$8:$A$47<=$A9)*$V$8:$V$47) -> 0 | AV9: =SUMPRODUCT(($D$8:$D$47=REGIONS!$B$12)*($A$8:$A$47<=$A9)*$L$8:$L$47)+SUMPRODUCT(($N$8:$N$47=REGIONS!$B$12)*($A$8:$A$47<=$A9)*$V$8:$V$47) -> 0 | AW9: =SUMPRODUCT(($D$8:$D$47=REGIONS!$B$13)*($A$8:$A$47<=$A9)*$L$8:$L$47)+SUMPRODUCT(($N$8:$N$47=REGIONS!$B$13)*($A$8:$A$47<=$A9)*$V$8:$V$47) -> 0 | AX9: =SUMPRODUCT(($D$8:$D$47=REGIONS!$B$14)*($A$8:$A$47<=$A9)*$L$8:$L$47)+SUMPRODUCT(($N$8:$N$47=REGIONS!$B$14)*($A$8:$A$47<=$A9)*$V$8:$V$47) -> 0 | AY9: =MAX(0,MIN(135,100-(MAX(0,-$AA9)*REGIONS!$E$7*ASSUMPTIONS!$B$7+MAX(0,$AA9-ASSUMPTIONS!$B$9)*REGIONS!$E$7*ASSUMPTIONS!$B$8)*(1-$AQ9/100))) -> 100 | AZ9: =MAX(0,MIN(135,100-(MAX(0,-$AB9)*REGIONS!$E$8*ASSUMPTIONS!$B$7+MAX(0,$AB9-ASSUMPTIONS!$B$9)*REGIONS!$E$8*ASSUMPTIONS!$B$8)*(1-$AR9/100))) -> 100 | BA9: =MAX(0,MIN(135,100-(MAX(0,-$AC9)*REGIONS!$E$9*ASSUMPTIONS!$B$7+MAX(0,$AC9-ASSUMPTIONS!$B$9)*REGIONS!$E$9*ASSUMPTIONS!$B$8)*(1-$AS9/100))) -> 100 | BB9: =MAX(0,MIN(135,100-(MAX(0,-$AD9)*REGIONS!$E$10*ASSUMPTIONS!$B$7+MAX(0,$AD9-ASSUMPTIONS!$B$9)*REGIONS!$E$10*ASSUMPTIONS!$B$8)*(1-$AT9/100))) -> 95.79328 | BC9: =MAX(0,MIN(135,100-(MAX(0,-$AE9)*REGIONS!$E$11*ASSUMPTIONS!$B$7+MAX(0,$AE9-ASSUMPTIONS!$B$9)*REGIONS!$E$11*ASSUMPTIONS!$B$8)*(1-$AU9/100))) -> 86.86226 | BD9: =MAX(0,MIN(135,100-(MAX(0,-$AF9)*REGIONS!$E$12*ASSUMPTIONS!$B$7+MAX(0,$AF9-ASSUMPTIONS!$B$9)*REGIONS!$E$12*ASSUMPTIONS!$B$8)*(1-$AV9/100))) -> 74.55822 | BE9: =MAX(0,MIN(135,100-(MAX(0,-$AG9)*REGIONS!$E$13*ASSUMPTIONS!$B$7+MAX(0,$AG9-ASSUMPTIONS!$B$9)*REGIONS!$E$13*ASSUMPTIONS!$B$8)*(1-$AW9/100))) -> 100 | BF9: =MAX(0,MIN(135,100-(MAX(0,-$AH9)*REGIONS!$E$14*ASSUMPTIONS!$B$7+MAX(0,$AH9-ASSUMPTIONS!$B$9)*REGIONS!$E$14*ASSUMPTIONS!$B$8)*(1-$AX9/100))) -> 100 | BG9: =$AY9*REGIONS!$D$7/100+$AZ9*REGIONS!$D$8/100+$BA9*REGIONS!$D$9/100+$BB9*REGIONS!$D$10/100+$BC9*REGIONS!$D$11/100+$BD9*REGIONS!$D$12/100+$BE9*REGIONS!$D$13/100+$BF9*REGIONS!$D$14/100 -> 95.885337 | BH9: =100*(100/MAX(1,$BG9))^ASSUMPTIONS!$B$10 -> 107.85643 | BI9: =$AY9*$BH9/100*ASSUMPTIONS!$B$11 -> 91.677966 | BJ9: =MAX(0,ABS($AA9)-$AI9*ASSUMPTIONS!$B$24)*REGIONS!$D$7/100+MAX(0,ABS($AB9)-$AJ9*ASSUMPTIONS!$B$24)*REGIONS!$D$8/100+MAX(0,ABS($AC9)-$AK9*ASSUMPTIONS!$B$24)*REGIONS!$D$9/100+MAX(0,ABS($AD9)-$AL9*ASSUMPTIONS!$B$24)*REGIONS!$D$10/100+MAX(0,ABS($AE9)-$AM9*ASSUMPTIONS!$B$24)*REGIONS!$D$11/100+MAX(0,ABS($AF9)-$AN9*ASSUMPTIONS!$B$24)*REGIONS!$D$12/100+MAX(0,ABS($AG9)-$AO9*ASSUMPTIONS!$B$24)*REGIONS!$D$13/100+MAX(0,ABS($AH9)-$AP9*ASSUMPTIONS!$B$24)*REGIONS!$D$14/100 -> 0.125861 | BK9: =MIN(ASSUMPTIONS!$B$14,ASSUMPTIONS!$B$12+$BJ9*ASSUMPTIONS!$B$13) -> 33.286162 | BL9: =$H9+$R9 -> 0 | BM9: =PLAY!$H9 -> 0 | BN9: =$BI9*ASSUMPTIONS!$B$15+$BK9*ASSUMPTIONS!$B$16 -> 40.958902 | BO9: =$BO8+$BN9-$BL9-$BM9-ASSUMPTIONS!$B$23 -> 98.833468 | BP9: =(SUMPRODUCT(($F$8:$F$8+$A$8:$A$8=$A9)*($C$8:$C$8<>"NONE")*$G$8:$G$8)+SUMPRODUCT(($P$8:$P$8+$A$8:$A$8=$A9)*($M$8:$M$8<>"NONE")*$Q$8:$Q$8))*(1+ASSUMPTIONS!$B$22*(MAX(0,ABS($AA9)/$AI9-1)+MAX(0,ABS($AB9)/$AJ9-1)+MAX(0,ABS($AC9)/$AK9-1)+MAX(0,ABS($AD9)/$AL9-1)+MAX(0,ABS($AE9)/$AM9-1)+MAX(0,ABS($AF9)/$AN9-1)+MAX(0,ABS($AG9)/$AO9-1)+MAX(0,ABS($AH9)/$AP9-1))/8) -> 2.1120288 | BQ9: =MAX(0,$BQ8*(1-ASSUMPTIONS!$B$18)+$BP9-$BM9*ASSUMPTIONS!$B$17) -> 2.1120288
